Workbook

Sheet NETFLIX
L11: ="GANANCIAS: "&SUM(I14:I866) -> GANANCIAS: 68
K12: =TODAY() -> 45392 | L12: BOTONES | P12: DATOS DE LA CUENTA
C13: PERFIL | D13: NOMBRE | E13: CELULAR | F13: PIN | G13: CORREO | H13: CLAVE | I13: PAGÓ | J13: TERMINA | K13: DIAS | L13: COBRAR | M13: RTB | N13: PERFILES | O13: PROOVEDOR | P13: COSTÓ | Q13: TERMINA | R13: DIAS
C14: 37438 | D14: Adriana | E14: 51 901 338 178 | F14: 1593 | G14: yeefong_0912@gmavea.com | H14: enmanuel24 | I14: 10 | J14: 09/04/2024 | K14: =J14-K$12 -> -1 | L14: =HYPERLINK("https://api.whatsapp.com/send?phone="&E14&"&text="&(IF(K14<=0,"🚨 Hola, *"&D14&".*"&"%0A"&"Su cuenta de Netflix vencio, Porfavor renueve si aun desea el servicio."&"%0A"&"*Tiene todo el dia para realizar el pago de lo contrario al dia siguiente sera suspendida*"&"%0A"&"*GRACIAS*","*MENSAJE RECORDATORIO 🚨*"&"%0A"&"%0A"&"Hola, "&D14&"."&"%0A"&"Te quedan "&K14&" Dias restantes para renovar su cuenta de *Netflix Premium*")),"💰") -> 💰 | M14: =HYPERLINK("https://api.whatsapp.com/send?phone="&E14&"&text=*🔴 CAMBIO DE CONTRASEÑA*"&"%0A"&"%0A"&"💻 Correo: *"&G14&"*"&"%0A"&"🔐 Nueva Contraseña: *"&H14&"*","🔐") -> 🔐 | N14: =HYPERLINK("https://api.whatsapp.com/send?phone=51"&E14&"&text=*🔴 NETFLIX ULTRA HD*"&"%0A"&"%0A"&"*📧 Correo:* "&G14&"%0A"&"*🔑 Contraseña:* "&H14&"%0A"&"%0A"&"*🖥 Perfil:* "&D14&" - "&PRIME!F14&"%0A"&"%0A"&"*📍 Vence:* "&J14,"💻") -> 💻 | O14: emanuel | P14: S/8. 5 | Q14: 09/04/2024 | R14: =Q14-TODAY() -> -1
C15: Andrea | D15: Andrea | E15: **** | F15: 121212 | G15: ricardosanuno@onlynett.com | H15: faid7070 | I15: 10 | J15: 11/04/2024 | K15: =J15-K$12 -> 1 | L15: =HYPERLINK("https://api.whatsapp.com/send?phone="&E15&"&text="&(IF(K15<=0,"🚨 Hola, *"&D15&".*"&"%0A"&"Su cuenta de Netflix vencio, Porfavor renueve si aun desea el servicio."&"%0A"&"*Tiene todo el dia para realizar el pago de lo contrario al dia siguiente sera suspendida*"&"%0A"&"*GRACIAS*","*MENSAJE RECORDATORIO 🚨*"&"%0A"&"%0A"&"Hola, "&D15&"."&"%0A"&"Te quedan "&K15&" Dias restantes para renovar su cuenta de *Netflix Premium*")),"💰") -> 💰 | M15: =HYPERLINK("https://api.whatsapp.com/send?phone="&E15&"&text=*🔴 CAMBIO DE CONTRASEÑA*"&"%0A"&"%0A"&"💻 Correo: *"&G15&"*"&"%0A"&"🔐 Nueva Contraseña: *"&H15&"*","🔐") -> 🔐 | N15: =HYPERLINK("https://api.whatsapp.com/send?phone=51"&E15&"&text=*🔴 NETFLIX ULTRA HD*"&"%0A"&"%0A"&"*📧 Correo:* "&G15&"%0A"&"*🔑 Contraseña:* "&H15&"%0A"&"%0A"&"*🖥 Perfil:* "&D15&" - "&PRIME!F15&"%0A"&"%0A"&"*📍 Vence:* "&J15,"💻") -> 💻 | O15: Saturnimo | P15: 8 | Q15: 11/04/2024 | R15: =Q15-TODAY() -> 1
C16: cristian | D16: cristian | E16: +51 937 160 701 | F16: 1996 | G16: zarole2000@gmastk.vip | H16: pitufo23 | I16: 12 | J16: 28/04/2024 | K16: =J16-K$12 -> 18 | L16: =HYPERLINK("https://api.whatsapp.com/send?phone="&E16&"&text="&(IF(K16<=0,"🚨 Hola, *"&D16&".*"&"%0A"&"Su cuenta de Netflix vencio, Porfavor renueve si aun desea el servicio."&"%0A"&"*Tiene todo el dia para realizar el pago de lo contrario al dia siguiente sera suspendida*"&"%0A"&"*GRACIAS*","*MENSAJE RECORDATORIO 🚨*"&"%0A"&"%0A"&"Hola, "&D16&"."&"%0A"&"Te quedan "&K16&" Dias restantes para renovar su cuenta de *Netflix Premium*")),"💰") -> 💰 | M16: =HYPERLINK("https://api.whatsapp.com/send?phone="&E16&"&text=*🔴 CAMBIO DE CONTRASEÑA*"&"%0A"&"%0A"&"💻 Correo: *"&G16&"*"&"%0A"&"🔐 Nueva Contraseña: *"&H16&"*","🔐") -> 🔐 | N16: =HYPERLINK("https://api.whatsapp.com/send?phone=51"&E16&"&text=*🔴 NETFLIX ULTRA HD*"&"%0A"&"%0A"&"*📧 Correo:* "&G16&"%0A"&"*🔑 Contraseña:* "&H16&"%0A"&"%0A"&"*🖥 Perfil:* "&D16&" - "&PRIME!F16&"%0A"&"%0A"&"*📍 Vence:* "&J16,"💻") -> 💻 | O16: emanuel | P16: S/ 8.5 | Q16: 28/04/2024 | R16: =Q16-TODAY() -> 18
C17: perfil 2 | D17: charly | E17: 51 954 931 852 | F17: **** | G17: calikenyin@onlynett.com | H17: faid7070 | I17: 12 | J17: 28/04/2024 | K17: =J17-K$12 -> 18 | L17: =HYPERLINK("https://api.whatsapp.com/send?phone="&E17&"&text="&(IF(K17<=0,"🚨 Hola, *"&D17&".*"&"%0A"&"Su cuenta de Netflix vencio, Porfavor renueve si aun desea el servicio."&"%0A"&"*Tiene todo el dia para realizar el pago de lo contrario al dia siguiente sera suspendida*"&"%0A"&"*GRACIAS*","*MENSAJE RECORDATORIO 🚨*"&"%0A"&"%0A"&"Hola, "&D17&"."&"%0A"&"Te quedan "&K17&" Dias restantes para renovar su cuenta de *Netflix Premium*")),"💰") -> 💰 | M17: =HYPERLINK("https://api.whatsapp.com/send?phone="&E17&"&text=*🔴 CAMBIO DE CONTRASEÑA*"&"%0A"&"%0A"&"💻 Correo: *"&G17&"*"&"%0A"&"🔐 Nueva Contraseña: *"&H17&"*","🔐") -> 🔐 | N17: =HYPERLINK("https://api.whatsapp.com/send?phone=51"&E17&"&text=*🔴 NETFLIX ULTRA HD*"&"%0A"&"%0A"&"*📧 Correo:* "&G17&"%0A"&"*🔑 Contraseña:* "&H17&"%0A"&"%0A"&"*🖥 Perfil:* "&D17&" - "&PRIME!F17&"%0A"&"%0A"&"*📍 Vence:* "&J17,"💻") -> 💻 | O17: Saturnimo | P17: 8 | Q17: 28/04/2024 | R17: =Q17-TODAY() -> 18
C18: Renzo | D18: Renzo | E18: 51 918 482 644 | F18: **** | G18: calikenyin@onlynett.com | H18: faid7070 | I18: 12 | J18: 04/05/2024 | K18: =J18-K$12 -> 24 | L18: =HYPERLINK("https://api.whatsapp.com/send?phone="&E18&"&text="&(IF(K18<=0,"🚨 Hola, *"&D18&".*"&"%0A"&"Su cuenta de Netflix vencio, Porfavor renueve si aun desea el servicio."&"%0A"&"*Tiene todo el dia para realizar el pago de lo contrario al dia siguiente sera suspendida*"&"%0A"&"*GRACIAS*","*MENSAJE RECORDATORIO 🚨*"&"%0A"&"%0A"&"Hola, "&D18&"."&"%0A"&"Te quedan "&K18&" Dias restantes para renovar su cuenta de *Netflix Premium*")),"💰") -> 💰 | M18: =HYPERLINK("https://api.whatsapp.com/send?phone="&E18&"&text=*🔴 CAMBIO DE CONTRASEÑA*"&"%0A"&"%0A"&"💻 Correo: *"&G18&"*"&"%0A"&"🔐 Nueva Contraseña: *"&H18&"*","🔐") -> 🔐 | N18: =HYPERLINK("https://api.whatsapp.com/send?phone=51"&E18&"&text=*🔴 NETFLIX ULTRA HD*"&"%0A"&"%0A"&"*📧 Correo:* "&G18&"%0A"&"*🔑 Contraseña:* "&H18&"%0A"&"%0A"&"*🖥 Perfil:* "&D18&" - "&PRIME!F18&"%0A"&"%0A"&"*📍 Vence:* "&J18,"💻") -> 💻 | O18: Saturnimo | P18: 8 | Q18: 04/05/2024 | R18: =Q18-TODAY() -> 24
C19: perfil2 | D19: Enzo | E19: 51 955 269 239 | F19: **** | G19: ricardosanuno@onlynett.com | H19: faid7070 | I19: 12 | J19: 08/05/2024 | K19: =J19-K$12 -> 28 | L19: =HYPERLINK("https://api.whatsapp.com/send?phone="&E19&"&text="&(IF(K19<=0,"🚨 Hola, *"&D19&".*"&"%0A"&"Su cuenta de Netflix vencio, Porfavor renueve si aun desea el servicio."&"%0A"&"*Tiene todo el dia para realizar el pago de lo contrario al dia siguiente sera suspendida*"&"%0A"&"*GRACIAS*","*MENSAJE RECORDATORIO 🚨*"&"%0A"&"%0A"&"Hola, "&D19&"."&"%0A"&"Te quedan "&K19&" Dias restantes para renovar su cuenta de *Netflix Premium*")),"💰") -> 💰 | M19: =HYPERLINK("https://api.whatsapp.com/send?phone="&E19&"&text=*🔴 CAMBIO DE CONTRASEÑA*"&"%0A"&"%0A"&"💻 Correo: *"&G19&"*"&"%0A"&"🔐 Nueva Contraseña: *"&H19&"*","🔐") -> 🔐 | N19: =HYPERLINK("https://api.whatsapp.com/send?phone=51"&E19&"&text=*🔴 NETFLIX ULTRA HD*"&"%0A"&"%0A"&"*📧 Correo:* "&G19&"%0A"&"*🔑 Contraseña:* "&H19&"%0A"&"%0A"&"*🖥 Perfil:* "&D19&" - "&PRIME!F25&"%0A"&"%0A"&"*📍 Vence:* "&J19,"💻") -> 💻 | O19: Saturnimo | P19: 8 | Q19: 08/05/2024 | R19: =Q19-TODAY() -> 28
K20: =J20-K$12 -> -45392 | L20: =HYPERLINK("https://api.whatsapp.com/send?phone="&E20&"&text="&(IF(K20<=0,"🚨 Hola, *"&D20&".*"&"%0A"&"Su cuenta de Netflix vencio, Porfavor renueve si aun desea el servicio."&"%0A"&"*Tiene todo el dia para realizar el pago de lo contrario al dia siguiente sera suspendida*"&"%0A"&"*GRACIAS*","*MENSAJE RECORDATORIO 🚨*"&"%0A"&"%0A"&"Hola, "&D20&"."&"%0A"&"Te quedan "&K20&" Dias restantes para renovar su cuenta de *Netflix Premium*")),"💰") -> 💰 | M20: =HYPERLINK("https://api.whatsapp.com/send?phone="&E20&"&text=*🔴 CAMBIO DE CONTRASEÑA*"&"%0A"&"%0A"&"💻 Correo: *"&G20&"*"&"%0A"&"🔐 Nueva Contraseña: *"&H20&"*","🔐") -> 🔐 | N20: =HYPERLINK("https://api.whatsapp.com/send?phone=51"&E20&"&text=*🔴 NETFLIX ULTRA HD*"&"%0A"&"%0A"&"*📧 Correo:* "&G20&"%0A"&"*🔑 Contraseña:* "&H20&"%0A"&"%0A"&"*🖥 Perfil:* "&D20&" - "&PRIME!F26&"%0A"&"%0A"&"*📍 Vence:* "&J20,"💻") -> 💻 | R20: =Q20-TODAY() -> -45392
K21: =J21-K$12 -> -45392 | L21: =HYPERLINK("https://api.whatsapp.com/send?phone="&E21&"&text="&(IF(K21<=0,"🚨 Hola, *"&D21&".*"&"%0A"&"Su cuenta de Netflix vencio, Porfavor renueve si aun desea el servicio."&"%0A"&"*Tiene todo el dia para realizar el pago de lo contrario al dia siguiente sera suspendida*"&"%0A"&"*GRACIAS*","*MENSAJE RECORDATORIO 🚨*"&"%0A"&"%0A"&"Hola, "&D21&"."&"%0A"&"Te quedan "&K21&" Dias restantes para renovar su cuenta de *Netflix Premium*")),"💰") -> 💰 | M21: =HYPERLINK("https://api.whatsapp.com/send?phone="&E21&"&text=*🔴 CAMBIO DE CONTRASEÑA*"&"%0A"&"%0A"&"💻 Correo: *"&G21&"*"&"%0A"&"🔐 Nueva Contraseña: *"&H21&"*","🔐") -> 🔐 | N21: =HYPERLINK("https://api.whatsapp.com/send?phone=51"&E21&"&text=*🔴 NETFLIX ULTRA HD*"&"%0A"&"%0A"&"*📧 Correo:* "&G21&"%0A"&"*🔑 Contraseña:* "&H21&"%0A"&"%0A"&"*🖥 Perfil:* "&D21&" - "&PRIME!F27&"%0A"&"%0A"&"*📍 Vence:* "&J21,"💻") -> 💻 | R21: =Q21-TODAY() -> -45392
K22: =J22-K$12 -> -45392 | L22: =HYPERLINK("https://api.whatsapp.com/send?phone="&E22&"&text="&(IF(K22<=0,"🚨 Hola, *"&D22&".*"&"%0A"&"Su cuenta de Netflix vencio, Porfavor renueve si aun desea el servicio."&"%0A"&"*Tiene todo el dia para realizar el pago de lo contrario al dia siguiente sera suspendida*"&"%0A"&"*GRACIAS*","*MENSAJE RECORDATORIO 🚨*"&"%0A"&"%0A"&"Hola, "&D22&"."&"%0A"&"Te quedan "&K22&" Dias restantes para renovar su cuenta de *Netflix Premium*")),"💰") -> 💰 | M22: =HYPERLINK("https://api.whatsapp.com/send?phone="&E22&"&text=*🔴 CAMBIO DE CONTRASEÑA*"&"%0A"&"%0A"&"💻 Correo: *"&G22&"*"&"%0A"&"🔐 Nueva Contraseña: *"&H22&"*","🔐") -> 🔐 | N22: =HYPERLINK("https://api.whatsapp.com/send?phone=51"&E22&"&text=*🔴 NETFLIX ULTRA HD*"&"%0A"&"%0A"&"*📧 Correo:* "&G22&"%0A"&"*🔑 Contraseña:* "&H22&"%0A"&"%0A"&"*🖥 Perfil:* "&D22&" - "&PRIME!F28&"%0A"&"%0A"&"*📍 Vence:* "&J22,"💻") -> 💻 | R22: =Q22-TODAY() -> -45392
K23: =J23-K$12 -> -45392 | L23: =HYPERLINK("https://api.whatsapp.com/send?phone="&E23&"&text="&(IF(K23<=0,"🚨 Hola, *"&D23&".*"&"%0A"&"Su cuenta de Netflix vencio, Porfavor renueve si aun desea el servicio."&"%0A"&"*Tiene todo el dia para realizar el pago de lo contrario al dia siguiente sera suspendida*"&"%0A"&"*GRACIAS*","*MENSAJE RECORDATORIO 🚨*"&"%0A"&"%0A"&"Hola, "&D23&"."&"%0A"&"Te quedan "&K23&" Dias restantes para renovar su cuenta de *Netflix Premium*")),"💰") -> 💰 | M23: =HYPERLINK("https://api.whatsapp.com/send?phone="&E23&"&text=*🔴 CAMBIO DE CONTRASEÑA*"&"%0A"&"%0A"&"💻 Correo: *"&G23&"*"&"%0A"&"🔐 Nueva Contraseña: *"&H23&"*","🔐") -> 🔐 | N23: =HYPERLINK("https://api.whatsapp.com/send?phone=51"&E23&"&text=*🔴 NETFLIX ULTRA HD*"&"%0A"&"%0A"&"*📧 Correo:* "&G23&"%0A"&"*🔑 Contraseña:* "&H23&"%0A"&"%0A"&"*🖥 Perfil:* "&D23&" - "&PRIME!F29&"%0A"&"%0A"&"*📍 Vence:* "&J23,"💻") -> 💻 | R23: =Q23-TODAY() -> -45392
K24: =J24-K$12 -> -45392 | L24: =HYPERLINK("https://api.whatsapp.com/send?phone="&E24&"&text="&(IF(K24<=0,"🚨 Hola, *"&D24&".*"&"%0A"&"Su cuenta de Netflix vencio, Porfavor renueve si aun desea el servicio."&"%0A"&"*Tiene todo el dia para realizar el pago de lo contrario al dia siguiente sera suspendida*"&"%0A"&"*GRACIAS*","*MENSAJE RECORDATORIO 🚨*"&"%0A"&"%0A"&"Hola, "&D24&"."&"%0A"&"Te quedan "&K24&" Dias restantes para renovar su cuenta de *Netflix Premium*")),"💰") -> 💰 | M24: =HYPERLINK("https://api.whatsapp.com/send?phone="&E24&"&text=*🔴 CAMBIO DE CONTRASEÑA*"&"%0A"&"%0A"&"💻 Correo: *"&G24&"*"&"%0A"&"🔐 Nueva Contraseña: *"&H24&"*","🔐") -> 🔐 | N24: =HYPERLINK("https://api.whatsapp.com/send?phone=51"&E24&"&text=*🔴 NETFLIX ULTRA HD*"&"%0A"&"%0A"&"*📧 Correo:* "&G24&"%0A"&"*🔑 Contraseña:* "&H24&"%0A"&"%0A"&"*🖥 Perfil:* "&D24&" - "&PRIME!F30&"%0A"&"%0A"&"*📍 Vence:* "&J24,"💻") -> 💻 | R24: =Q24-TODAY() -> -45392
K25: =J25-K$12 -> -45392 | L25: =HYPERLINK("https://api.whatsapp.com/send?phone="&E25&"&text="&(IF(K25<=0,"🚨 Hola, *"&D25&".*"&"%0A"&"Su cuenta de Netflix vencio, Porfavor renueve si aun desea el servicio."&"%0A"&"*Tiene todo el dia para realizar el pago de lo contrario al dia siguiente sera suspendida*"&"%0A"&"*GRACIAS*","*MENSAJE RECORDATORIO 🚨*"&"%0A"&"%0A"&"Hola, "&D25&"."&"%0A"&"Te quedan "&K25&" Dias restantes para renovar su cuenta de *Netflix Premium*")),"💰") -> 💰 | M25: =HYPERLINK("https://api.whatsapp.com/send?phone="&E25&"&text=*🔴 CAMBIO DE CONTRASEÑA*"&"%0A"&"%0A"&"💻 Correo: *"&G25&"*"&"%0A"&"🔐 Nueva Contraseña: *"&H25&"*","🔐") -> 🔐 | N25: =HYPERLINK("https://api.whatsapp.com/send?phone=51"&E25&"&text=*🔴 NETFLIX ULTRA HD*"&"%0A"&"%0A"&"*📧 Correo:* "&G25&"%0A"&"*🔑 Contraseña:* "&H25&"%0A"&"%0A"&"*🖥 Perfil:* "&D25&" - "&PRIME!F31&"%0A"&"%0A"&"*📍 Vence:* "&J25,"💻") -> 💻 | R25: =Q25-TODAY() -> -45392
K26: =J26-K$12 -> -45392 | L26: =HYPERLINK("https://api.whatsapp.com/send?phone="&E26&"&text="&(IF(K26<=0,"🚨 Hola, *"&D26&".*"&"%0A"&"Su cuenta de Netflix vencio, Porfavor renueve si aun desea el servicio."&"%0A"&"*Tiene todo el dia para realizar el pago de lo contrario al dia siguiente sera suspendida*"&"%0A"&"*GRACIAS*","*MENSAJE RECORDATORIO 🚨*"&"%0A"&"%0A"&"Hola, "&D26&"."&"%0A"&"Te quedan "&K26&" Dias restantes para renovar su cuenta de *Netflix Premium*")),"💰") -> 💰 | M26: =HYPERLINK("https://api.whatsapp.com/send?phone="&E26&"&text=*🔴 CAMBIO DE CONTRASEÑA*"&"%0A"&"%0A"&"💻 Correo: *"&G26&"*"&"%0A"&"🔐 Nueva Contraseña: *"&H26&"*","🔐") -> 🔐 | N26: =HYPERLINK("https://api.whatsapp.com/send?phone=51"&E26&"&text=*🔴 NETFLIX ULTRA HD*"&"%0A"&"%0A"&"*📧 Correo:* "&G26&"%0A"&"*🔑 Contraseña:* "&H26&"%0A"&"%0A"&"*🖥 Perfil:* "&D26&" - "&PRIME!F32&"%0A"&"%0A"&"*📍 Vence:* "&J26,"💻") -> 💻 | R26: =Q26-TODAY() -> -45392
K27: =J27-K$12 -> -45392 | L27: =HYPERLINK("https://api.whatsapp.com/send?phone="&E27&"&text="&(IF(K27<=0,"🚨 Hola, *"&D27&".*"&"%0A"&"Su cuenta de Netflix vencio, Porfavor renueve si aun desea el servicio."&"%0A"&"*Tiene todo el dia para realizar el pago de lo contrario al dia siguiente sera suspendida*"&"%0A"&"*GRACIAS*","*MENSAJE RECORDATORIO 🚨*"&"%0A"&"%0A"&"Hola, "&D27&"."&"%0A"&"Te quedan "&K27&" Dias restantes para renovar su cuenta de *Netflix Premium*")),"💰") -> 💰 | M27: =HYPERLINK("https://api.whatsapp.com/send?phone="&E27&"&text=*🔴 CAMBIO DE CONTRASEÑA*"&"%0A"&"%0A"&"💻 Correo: *"&G27&"*"&"%0A"&"🔐 Nueva Contraseña: *"&H27&"*","🔐") -> 🔐 | N27: =HYPERLINK("https://api.whatsapp.com/send?phone=51"&E27&"&text=*🔴 NETFLIX ULTRA HD*"&"%0A"&"%0A"&"*📧 Correo:* "&G27&"%0A"&"*🔑 Contraseña:* "&H27&"%0A"&"%0A"&"*🖥 Perfil:* "&D27&" - "&PRIME!F33&"%0A"&"%0A"&"*📍 Vence:* "&J27,"💻") -> 💻 | R27: =Q27-TODAY() -> -45392
K28: =J28-K$12 -> -45392 | L28: =HYPERLINK("https://api.whatsapp.com/send?phone="&E28&"&text="&(IF(K28<=0,"🚨 Hola, *"&D28&".*"&"%0A"&"Su cuenta de Netflix vencio, Porfavor renueve si aun desea el servicio."&"%0A"&"*Tiene todo el dia para realizar el pago de lo contrario al dia siguiente sera suspendida*"&"%0A"&"*GRACIAS*","*MENSAJE RECORDATORIO 🚨*"&"%0A"&"%0A"&"Hola, "&D28&"."&"%0A"&"Te quedan "&K28&" Dias restantes para renovar su cuenta de *Netflix Premium*")),"💰") -> 💰 | M28: =HYPERLINK("https://api.whatsapp.com/send?phone="&E28&"&text=*🔴 CAMBIO DE CONTRASEÑA*"&"%0A"&"%0A"&"💻 Correo: *"&G28&"*"&"%0A"&"🔐 Nueva Contraseña: *"&H28&"*","🔐") -> 🔐 | N28: =HYPERLINK("https://api.whatsapp.com/send?phone=51"&E28&"&text=*🔴 NETFLIX ULTRA HD*"&"%0A"&"%0A"&"*📧 Correo:* "&G28&"%0A"&"*🔑 Contraseña:* "&H28&"%0A"&"%0A"&"*🖥 Perfil:* "&D28&" - "&PRIME!F34&"%0A"&"%0A"&"*📍 Vence:* "&J28,"💻") -> 💻 | R28: =Q28-TODAY() -> -45392

Sheet COMBO PLUS
L11: ="GANANCIAS: "&SUM(I14:I866) -> GANANCIAS: 12
K12: =TODAY() -> 45392 | L12: BOTONES | P12: DATOS DE LA CUENTA
C13: PERFIL | D13: NOMBRE | E13: CELULAR | F13: PIN | G13: CORREO | H13: CLAVE | I13: PAGÓ | J13: TERMINA | K13: DIAS | L13: COBRAR | M13: RTB | N13: PERFILES | O13: PROOVEDOR | P13: COSTÓ | Q13: TERMINA | R13: DIAS
C14: Misa | D14: Misael | E14: 945174408 | F14: 2485 | G14: combo.prueba@gmail.com | H14: PRUEBA | I14: 12 | J14: 30/8/23 | K14: =J14-K$12 -> -224 | L14: =HYPERLINK("https://api.whatsapp.com/send?phone="&E14&"&text="&(IF(K14<=0,"🚨 Hola, *"&D14&".*"&"%0A"&"Su cuenta de Combo Plus vencio, Porfavor renueve si aun desea el servicio."&"%0A"&"*Tiene todo el dia para realizar el pago de lo contrario al dia siguiente sera suspendida*"&"%0A"&"*GRACIAS*","*MENSAJE RECORDATORIO 🚨*"&"%0A"&"%0A"&"Hola, "&D14&"."&"%0A"&"Te quedan "&K14&" Dias restantes para renovar su cuenta de *COMBO PLUS*")),"💰") -> 💰 | M14: =HYPERLINK("https://api.whatsapp.com/send?phone="&E14&"&text=*🔴Cambio de contraseña: Combo Plus*"&"%0A"&"%0A"&"💻 Correo: *"&G14&"*"&"%0A"&"🔐 Nueva Contraseña: *"&H14&"*","🔐") -> 🔐 | N14: =HYPERLINK("https://api.whatsapp.com/send?phone=51"&E14&"&text=*🔴COMBO PLUS*"&"%0A"&"%0A"&"*📧 Correo:* "&G14&"%0A"&"*🔑 Contraseña:* "&H14&"%0A"&"%0A"&"*🖥 Perfil:* "&D14&" - "&F14&"%0A"&"%0A"&"*📍 Vence:* "&J14,"💻") -> 💻 | O14: MISAEL | P14: 8 | Q14: 30/9/23 | R14: =Q14-TODAY() -> -193
K15: =J15-K$12 -> -45392 | L15: =HYPERLINK("https://api.whatsapp.com/send?phone="&E15&"&text="&(IF(K15<=0,"🚨 Hola, *"&D15&".*"&"%0A"&"Su cuenta de Combo Plus vencio, Porfavor renueve si aun desea el servicio."&"%0A"&"*Tiene todo el dia para realizar el pago de lo contrario al dia siguiente sera suspendida*"&"%0A"&"*GRACIAS*","*MENSAJE RECORDATORIO 🚨*"&"%0A"&"%0A"&"Hola, "&D15&"."&"%0A"&"Te quedan "&K15&" Dias restantes para renovar su cuenta de *COMBO PLUS*")),"💰") -> 💰 | M15: =HYPERLINK("https://api.whatsapp.com/send?phone="&E15&"&text=*🔴Cambio de contraseña: Combo Plus*"&"%0A"&"%0A"&"💻 Correo: *"&G15&"*"&"%0A"&"🔐 Nueva Contraseña: *"&H15&"*","🔐") -> 🔐 | N15: =HYPERLINK("https://api.whatsapp.com/send?phone=51"&E15&"&text=*🔴COMBO PLUS*"&"%0A"&"%0A"&"*📧 Correo:* "&G15&"%0A"&"*🔑 Contraseña:* "&H15&"%0A"&"%0A"&"*🖥 Perfil:* "&D15&" - "&F15&"%0A"&"%0A"&"*📍 Vence:* "&J15,"💻") -> 💻 | R15: =Q15-TODAY() -> -45392
K16: =J16-K$12 -> -45392 | L16: =HYPERLINK("https://api.whatsapp.com/send?phone="&E16&"&text="&(IF(K16<=0,"🚨 Hola, *"&D16&".*"&"%0A"&"Su cuenta de Combo Plus vencio, Porfavor renueve si aun desea el servicio."&"%0A"&"*Tiene todo el dia para realizar el pago de lo contrario al dia siguiente sera suspendida*"&"%0A"&"*GRACIAS*","*MENSAJE RECORDATORIO 🚨*"&"%0A"&"%0A"&"Hola, "&D16&"."&"%0A"&"Te quedan "&K16&" Dias restantes para renovar su cuenta de *COMBO PLUS*")),"💰") -> 💰 | M16: =HYPERLINK("https://api.whatsapp.com/send?phone="&E16&"&text=*🔴Cambio de contraseña: Combo Plus*"&"%0A"&"%0A"&"💻 Correo: *"&G16&"*"&"%0A"&"🔐 Nueva Contraseña: *"&H16&"*","🔐") -> 🔐 | N16: =HYPERLINK("https://api.whatsapp.com/send?phone=51"&E16&"&text=*🔴COMBO PLUS*"&"%0A"&"%0A"&"*📧 Correo:* "&G16&"%0A"&"*🔑 Contraseña:* "&H16&"%0A"&"%0A"&"*🖥 Perfil:* "&D16&" - "&F16&"%0A"&"%0A"&"*📍 Vence:* "&J16,"💻") -> 💻 | R16: =Q16-TODAY() -> -45392
K17: =J17-K$12 -> -45392 | L17: =HYPERLINK("https://api.whatsapp.com/send?phone="&E17&"&text="&(IF(K17<=0,"🚨 Hola, *"&D17&".*"&"%0A"&"Su cuenta de Combo Plus vencio, Porfavor renueve si aun desea el servicio."&"%0A"&"*Tiene todo el dia para realizar el pago de lo contrario al dia siguiente sera suspendida*"&"%0A"&"*GRACIAS*","*MENSAJE RECORDATORIO 🚨*"&"%0A"&"%0A"&"Hola, "&D17&"."&"%0A"&"Te quedan "&K17&" Dias restantes para renovar su cuenta de *COMBO PLUS*")),"💰") -> 💰 | M17: =HYPERLINK("https://api.whatsapp.com/send?phone="&E17&"&text=*🔴Cambio de contraseña: Combo Plus*"&"%0A"&"%0A"&"💻 Correo: *"&G17&"*"&"%0A"&"🔐 Nueva Contraseña: *"&H17&"*","🔐") -> 🔐 | N17: =HYPERLINK("https://api.whatsapp.com/send?phone=51"&E17&"&text=*🔴COMBO PLUS*"&"%0A"&"%0A"&"*📧 Correo:* "&G17&"%0A"&"*🔑 Contraseña:* "&H17&"%0A"&"%0A"&"*🖥 Perfil:* "&D17&" - "&F17&"%0A"&"%0A"&"*📍 Vence:* "&J17,"💻") -> 💻 | R17: =Q17-TODAY() -> -45392
K18: =J18-K$12 -> -45392 | L18: =HYPERLINK("https://api.whatsapp.com/send?phone="&E18&"&text="&(IF(K18<=0,"🚨 Hola, *"&D18&".*"&"%0A"&"Su cuenta de Combo Plus vencio, Porfavor renueve si aun desea el servicio."&"%0A"&"*Tiene todo el dia para realizar el pago de lo contrario al dia siguiente sera suspendida*"&"%0A"&"*GRACIAS*","*MENSAJE RECORDATORIO 🚨*"&"%0A"&"%0A"&"Hola, "&D18&"."&"%0A"&"Te quedan "&K18&" Dias restantes para renovar su cuenta de *COMBO PLUS*")),"💰") -> 💰 | M18: =HYPERLINK("https://api.whatsapp.com/send?phone="&E18&"&text=*🔴Cambio de contraseña: Combo Plus*"&"%0A"&"%0A"&"💻 Correo: *"&G18&"*"&"%0A"&"🔐 Nueva Contraseña: *"&H18&"*","🔐") -> 🔐 | N18: =HYPERLINK("https://api.whatsapp.com/send?phone=51"&E18&"&text=*🔴COMBO PLUS*"&"%0A"&"%0A"&"*📧 Correo:* "&G18&"%0A"&"*🔑 Contraseña:* "&H18&"%0A"&"%0A"&"*🖥 Perfil:* "&D18&" - "&F18&"%0A"&"%0A"&"*📍 Vence:* "&J18,"💻") -> 💻 | R18: =Q18-TODAY() -> -45392
K19: =J19-K$12 -> -45392 | L19: =HYPERLINK("https://api.whatsapp.com/send?phone="&E19&"&text="&(IF(K19<=0,"🚨 Hola, *"&D19&".*"&"%0A"&"Su cuenta de Combo Plus vencio, Porfavor renueve si aun desea el servicio."&"%0A"&"*Tiene todo el dia para realizar el pago de lo contrario al dia siguiente sera suspendida*"&"%0A"&"*GRACIAS*","*MENSAJE RECORDATORIO 🚨*"&"%0A"&"%0A"&"Hola, "&D19&"."&"%0A"&"Te quedan "&K19&" Dias restantes para renovar su cuenta de *COMBO PLUS*")),"💰") -> 💰 | M19: =HYPERLINK("https://api.whatsapp.com/send?phone="&E19&"&text=*🔴Cambio de contraseña: Combo Plus*"&"%0A"&"%0A"&"💻 Correo: *"&G19&"*"&"%0A"&"🔐 Nueva Contraseña: *"&H19&"*","🔐") -> 🔐 | N19: =HYPERLINK("https://api.whatsapp.com/send?phone=51"&E19&"&text=*🔴COMBO PLUS*"&"%0A"&"%0A"&"*📧 Correo:* "&G19&"%0A"&"*🔑 Contraseña:* "&H19&"%0A"&"%0A"&"*🖥 Perfil:* "&D19&" - "&F19&"%0A"&"%0A"&"*📍 Vence:* "&J19,"💻") -> 💻 | R19: =Q19-TODAY() -> -45392
K20: =J20-K$12 -> -45392 | L20: =HYPERLINK("https://api.whatsapp.com/send?phone="&E20&"&text="&(IF(K20<=0,"🚨 Hola, *"&D20&".*"&"%0A"&"Su cuenta de Combo Plus vencio, Porfavor renueve si aun desea el servicio."&"%0A"&"*Tiene todo el dia para realizar el pago de lo contrario al dia siguiente sera suspendida*"&"%0A"&"*GRACIAS*","*MENSAJE RECORDATORIO 🚨*"&"%0A"&"%0A"&"Hola, "&D20&"."&"%0A"&"Te quedan "&K20&" Dias restantes para renovar su cuenta de *COMBO PLUS*")),"💰") -> 💰 | M20: =HYPERLINK("https://api.whatsapp.com/send?phone="&E20&"&text=*🔴Cambio de contraseña: Combo Plus*"&"%0A"&"%0A"&"💻 Correo: *"&G20&"*"&"%0A"&"🔐 Nueva Contraseña: *"&H20&"*","🔐") -> 🔐 | N20: =HYPERLINK("https://api.whatsapp.com/send?phone=51"&E20&"&text=*🔴COMBO PLUS*"&"%0A"&"%0A"&"*📧 Correo:* "&G20&"%0A"&"*🔑 Contraseña:* "&H20&"%0A"&"%0A"&"*🖥 Perfil:* "&D20&" - "&F20&"%0A"&"%0A"&"*📍 Vence:* "&J20,"💻") -> 💻 | R20: =Q20-TODAY() -> -45392
D22: NOMBRE | E22: CELULAR | F22: PIN | G22: CORREO | H22: CLAVE | I22: PAGÓ | J22: TERMINA | K22: DIAS | L22: COBRAR | M22: RTB | N22: PERFILES | O22: PROOVEDOR | P22: COSTÓ | Q22: TERMINA | R22: DIAS
K23: =J23-K$12 -> -45392 | L23: =HYPERLINK("https://api.whatsapp.com/send?phone="&E23&"&text="&(IF(K23<=0,"🚨 Hola, *"&D23&".*"&"%0A"&"Su cuenta de Combo Plus vencio, Porfavor renueve si aun desea el servicio."&"%0A"&"*Tiene todo el dia para realizar el pago de lo contrario al dia siguiente sera suspendida*"&"%0A"&"*GRACIAS*","*MENSAJE RECORDATORIO 🚨*"&"%0A"&"%0A"&"Hola, "&D23&"."&"%0A"&"Te quedan "&K23&" Dias restantes para renovar su cuenta de *COMBO PLUS*")),"💰") -> 💰 | M23: =HYPERLINK("https://api.whatsapp.com/send?phone="&E23&"&text=*🔴Cambio de contraseña: Combo Plus*"&"%0A"&"%0A"&"💻 Correo: *"&G23&"*"&"%0A"&"🔐 Nueva Contraseña: *"&H23&"*","🔐") -> 🔐 | N23: =HYPERLINK("https://api.whatsapp.com/send?phone=51"&E23&"&text=*🔴COMBO PLUS COMPLETA*"&"%0A"&"%0A"&"*📧 Correo:* "&G23&"%0A"&"*🔑 Contraseña:* "&H23&"%0A"&"%0A"&"*🖥 Perfil:* "&D23&" "&F23&"%0A"&"%0A"&"*📍 Vence:* "&J23,"💻") -> 💻 | R23: =Q23-TODAY() -> -45392
K25: =TODAY() -> 45392 | L25: BOTONES | P25: DATOS DE LA CUENTA
C26: PERFIL | D26: NOMBRE | E26: CELULAR | F26: PIN | G26: CORREO | H26: CLAVE | I26: PAGÓ | J26: TERMINA | K26: DIAS | L26: COBRAR | M26: RTB | N26: PERFILES | O26: PROOVEDOR | P26: COSTÓ | Q26: TERMINA | R26: DIAS
K27: =J27-K$12 -> -45392 | L27: =HYPERLINK("https://api.whatsapp.com/send?phone="&E27&"&text="&(IF(K27<=0,"🚨 Hola, *"&D27&".*"&"%0A"&"Su cuenta de Combo Plus vencio, Porfavor renueve si aun desea el servicio."&"%0A"&"*Tiene todo el dia para realizar el pago de lo contrario al dia siguiente sera suspendida*"&"%0A"&"*GRACIAS*","*MENSAJE RECORDATORIO 🚨*"&"%0A"&"%0A"&"Hola, "&D27&"."&"%0A"&"Te quedan "&K27&" Dias restantes para renovar su cuenta de *COMBO PLUS*")),"💰") -> 💰 | M27: =HYPERLINK("https://api.whatsapp.com/send?phone="&E27&"&text=*🔴Cambio de contraseña: Combo Plus*"&"%0A"&"%0A"&"💻 Correo: *"&G27&"*"&"%0A"&"🔐 Nueva Contraseña: *"&H27&"*","🔐") -> 🔐 | N27: =HYPERLINK("https://api.whatsapp.com/send?phone=51"&E27&"&text=*🔴COMBO PLUS*"&"%0A"&"%0A"&"*📧 Correo:* "&G27&"%0A"&"*🔑 Contraseña:* "&H27&"%0A"&"%0A"&"*🖥 Perfil:* "&D27&" - "&F27&"%0A"&"%0A"&"*📍 Vence:* "&J27,"💻") -> 💻 | R27: =Q27-TODAY() -> -45392
K28: =J28-K$12 -> -45392 | L28: =HYPERLINK("https://api.whatsapp.com/send?phone="&E28&"&text="&(IF(K28<=0,"🚨 Hola, *"&D28&".*"&"%0A"&"Su cuenta de Combo Plus vencio, Porfavor renueve si aun desea el servicio."&"%0A"&"*Tiene todo el dia para realizar el pago de lo contrario al dia siguiente sera suspendida*"&"%0A"&"*GRACIAS*","*MENSAJE RECORDATORIO 🚨*"&"%0A"&"%0A"&"Hola, "&D28&"."&"%0A"&"Te quedan "&K28&" Dias restantes para renovar su cuenta de *COMBO PLUS*")),"💰") -> 💰 | M28: =HYPERLINK("https://api.whatsapp.com/send?phone="&E28&"&text=*🔴Cambio de contraseña: Combo Plus*"&"%0A"&"%0A"&"💻 Correo: *"&G28&"*"&"%0A"&"🔐 Nueva Contraseña: *"&H28&"*","🔐") -> 🔐 | N28: =HYPERLINK("https://api.whatsapp.com/send?phone=51"&E28&"&text=*🔴COMBO PLUS*"&"%0A"&"%0A"&"*📧 Correo:* "&G28&"%0A"&"*🔑 Contraseña:* "&H28&"%0A"&"%0A"&"*🖥 Perfil:* "&D28&" - "&F28&"%0A"&"%0A"&"*📍 Vence:* "&J28,"💻") -> 💻 | R28: =Q28-TODAY() -> -45392
K29: =J29-K$12 -> -45392 | L29: =HYPERLINK("https://api.whatsapp.com/send?phone="&E29&"&text="&(IF(K29<=0,"🚨 Hola, *"&D29&".*"&"%0A"&"Su cuenta de Combo Plus vencio, Porfavor renueve si aun desea el servicio."&"%0A"&"*Tiene todo el dia para realizar el pago de lo contrario al dia siguiente sera suspendida*"&"%0A"&"*GRACIAS*","*MENSAJE RECORDATORIO 🚨*"&"%0A"&"%0A"&"Hola, "&D29&"."&"%0A"&"Te quedan "&K29&" Dias restantes para renovar su cuenta de *COMBO PLUS*")),"💰") -> 💰 | M29: =HYPERLINK("https://api.whatsapp.com/send?phone="&E29&"&text=*🔴Cambio de contraseña: Combo Plus*"&"%0A"&"%0A"&"💻 Correo: *"&G29&"*"&"%0A"&"🔐 Nueva Contraseña: *"&H29&"*","🔐") -> 🔐 | N29: =HYPERLINK("https://api.whatsapp.com/send?phone=51"&E29&"&text=*🔴COMBO PLUS*"&"%0A"&"%0A"&"*📧 Correo:* "&G29&"%0A"&"*🔑 Contraseña:* "&H29&"%0A"&"%0A"&"*🖥 Perfil:* "&D29&" - "&F29&"%0A"&"%0A"&"*📍 Vence:* "&J29,"💻") -> 💻 | R29: =Q29-TODAY() -> -45392
K30: =J30-K$12 -> -45392 | L30: =HYPERLINK("https://api.whatsapp.com/send?phone="&E30&"&text="&(IF(K30<=0,"🚨 Hola, *"&D30&".*"&"%0A"&"Su cuenta de Combo Plus vencio, Porfavor renueve si aun desea el servicio."&"%0A"&"*Tiene todo el dia para realizar el pago de lo contrario al dia siguiente sera suspendida*"&"%0A"&"*GRACIAS*","*MENSAJE RECORDATORIO 🚨*"&"%0A"&"%0A"&"Hola, "&D30&"."&"%0A"&"Te quedan "&K30&" Dias restantes para renovar su cuenta de *COMBO PLUS*")),"💰") -> 💰 | M30: =HYPERLINK("https://api.whatsapp.com/send?phone="&E30&"&text=*🔴Cambio de contraseña: Combo Plus*"&"%0A"&"%0A"&"💻 Correo: *"&G30&"*"&"%0A"&"🔐 Nueva Contraseña: *"&H30&"*","🔐") -> 🔐 | N30: =HYPERLINK("https://api.whatsapp.com/send?phone=51"&E30&"&text=*🔴COMBO PLUS*"&"%0A"&"%0A"&"*📧 Correo:* "&G30&"%0A"&"*🔑 Contraseña:* "&H30&"%0A"&"%0A"&"*🖥 Perfil:* "&D30&" - "&F30&"%0A"&"%0A"&"*📍 Vence:* "&J30,"💻") -> 💻 | R30: =Q30-TODAY() -> -45392
K31: =J31-K$12 -> -45392 | L31: =HYPERLINK("https://api.whatsapp.com/send?phone="&E31&"&text="&(IF(K31<=0,"🚨 Hola, *"&D31&".*"&"%0A"&"Su cuenta de Combo Plus vencio, Porfavor renueve si aun desea el servicio."&"%0A"&"*Tiene todo el dia para realizar el pago de lo contrario al dia siguiente sera suspendida*"&"%0A"&"*GRACIAS*","*MENSAJE RECORDATORIO 🚨*"&"%0A"&"%0A"&"Hola, "&D31&"."&"%0A"&"Te quedan "&K31&" Dias restantes para renovar su cuenta de *COMBO PLUS*")),"💰") -> 💰 | M31: =HYPERLINK("https://api.whatsapp.com/send?phone="&E31&"&text=*🔴Cambio de contraseña: Combo Plus*"&"%0A"&"%0A"&"💻 Correo: *"&G31&"*"&"%0A"&"🔐 Nueva Contraseña: *"&H31&"*","🔐") -> 🔐 | N31: =HYPERLINK("https://api.whatsapp.com/send?phone=51"&E31&"&text=*🔴COMBO PLUS*"&"%0A"&"%0A"&"*📧 Correo:* "&G31&"%0A"&"*🔑 Contraseña:* "&H31&"%0A"&"%0A"&"*🖥 Perfil:* "&D31&" - "&F31&"%0A"&"%0A"&"*📍 Vence:* "&J31,"💻") -> 💻 | R31: =Q31-TODAY() -> -45392
K32: =J32-K$12 -> -45392 | L32: =HYPERLINK("https://api.whatsapp.com/send?phone="&E32&"&text="&(IF(K32<=0,"🚨 Hola, *"&D32&".*"&"%0A"&"Su cuenta de Combo Plus vencio, Porfavor renueve si aun desea el servicio."&"%0A"&"*Tiene todo el dia para realizar el pago de lo contrario al dia siguiente sera suspendida*"&"%0A"&"*GRACIAS*","*MENSAJE RECORDATORIO 🚨*"&"%0A"&"%0A"&"Hola, "&D32&"."&"%0A"&"Te quedan "&K32&" Dias restantes para renovar su cuenta de *COMBO PLUS*")),"💰") -> 💰 | M32: =HYPERLINK("https://api.whatsapp.com/send?phone="&E32&"&text=*🔴Cambio de contraseña: Combo Plus*"&"%0A"&"%0A"&"💻 Correo: *"&G32&"*"&"%0A"&"🔐 Nueva Contraseña: *"&H32&"*","🔐") -> 🔐 | N32: =HYPERLINK("https://api.whatsapp.com/send?phone=51"&E32&"&text=*🔴COMBO PLUS*"&"%0A"&"%0A"&"*📧 Correo:* "&G32&"%0A"&"*🔑 Contraseña:* "&H32&"%0A"&"%0A"&"*🖥 Perfil:* "&D32&" - "&F32&"%0A"&"%0A"&"*📍 Vence:* "&J32,"💻") -> 💻 | R32: =Q32-TODAY() -> -45392
K33: =J33-K$12 -> -45392 | L33: =HYPERLINK("https://api.whatsapp.com/send?phone="&E33&"&text="&(IF(K33<=0,"🚨 Hola, *"&D33&".*"&"%0A"&"Su cuenta de Combo Plus vencio, Porfavor renueve si aun desea el servicio."&"%0A"&"*Tiene todo el dia para realizar el pago de lo contrario al dia siguiente sera suspendida*"&"%0A"&"*GRACIAS*","*MENSAJE RECORDATORIO 🚨*"&"%0A"&"%0A"&"Hola, "&D33&"."&"%0A"&"Te quedan "&K33&" Dias restantes para renovar su cuenta de *COMBO PLUS*")),"💰") -> 💰 | M33: =HYPERLINK("https://api.whatsapp.com/send?phone="&E33&"&text=*🔴Cambio de contraseña: Combo Plus*"&"%0A"&"%0A"&"💻 Correo: *"&G33&"*"&"%0A"&"🔐 Nueva Contraseña: *"&H33&"*","🔐") -> 🔐 | N33: =HYPERLINK("https://api.whatsapp.com/send?phone=51"&E33&"&text=*🔴COMBO PLUS*"&"%0A"&"%0A"&"*📧 Correo:* "&G33&"%0A"&"*🔑 Contraseña:* "&H33&"%0A"&"%0A"&"*🖥 Perfil:* "&D33&" - "&F33&"%0A"&"%0A"&"*📍 Vence:* "&J33,"💻") -> 💻 | R33: =Q33-TODAY() -> -45392

Sheet CLARO VIDEO
L11: ="GANANCIAS: "&SUM(I14:I866) -> GANANCIAS: 51
K12: =TODAY() -> 45392 | L12: BOTONES | P12: DATOS DE LA CUENTA
C13: PERFIL | D13: NOMBRE | E13: CELULAR | F13: VENDEDOR | G13: CORREO | H13: CLAVE | I13: PAGÓ | J13: TERMINA | K13: DIAS | L13: COBRAR | M13: RTB | N13: PERFILES | O13: PROOVEDOR | P13: COSTÓ | Q13: TERMINA | R13: DIAS
C14: Misa | D14: Misael | E14: 945174408 | F14: 1111 | G14: clarovideo@gmail.com | H14: PRUEBA | I14: 6 | J14: 30/8/23 | K14: =J14-K$12 -> -224 | L14: =HYPERLINK("https://api.whatsapp.com/send?phone="&E14&"&text="&(IF(K14<=0,"🚨 Hola, *"&D14&".*"&"%0A"&"Su cuenta de Claro Video vencio, Porfavor renueve si aun desea el servicio."&"%0A"&"*Tiene todo el dia para realizar el pago de lo contrario al dia siguiente sera suspendida*"&"%0A"&"*GRACIAS*","*MENSAJE RECORDATORIO 🚨*"&"%0A"&"%0A"&"Hola, "&D14&"."&"%0A"&"Te quedan "&K14&" Dias restantes para renovar su cuenta de *CLARO VIDEO*")),"💰") -> 💰 | M14: =HYPERLINK("https://api.whatsapp.com/send?phone="&E14&"&text=*🔴 Cambio de contraseña: Claro Video*"&"%0A"&"%0A"&"💻 Correo: *"&G14&"*"&"%0A"&"🔐 Nueva Contraseña: *"&H14&"*","🔐") -> 🔐 | N14: =HYPERLINK("https://api.whatsapp.com/send?phone=51"&E14&"&text=*🔴 CLARO VIDEO*"&"%0A"&"%0A"&"*📧 Correo:* "&G14&"%0A"&"*🔑 Contraseña:* "&H14&"%0A"&"%0A"&"*🖥 Perfil:* "&C14&"%0A"&"%0A"&"*📍 Vence:* "&J14,"💻") -> 💻 | O14: MISAEL | P14: 8 | Q14: 30/9/23 | R14: =Q14-TODAY() -> -193
K15: =J15-K$12 -> -45392 | L15: =HYPERLINK("https://api.whatsapp.com/send?phone="&E15&"&text="&(IF(K15<=0,"🚨 Hola, *"&D15&".*"&"%0A"&"Su cuenta de Claro Video vencio, Porfavor renueve si aun desea el servicio."&"%0A"&"*Tiene todo el dia para realizar el pago de lo contrario al dia siguiente sera suspendida*"&"%0A"&"*GRACIAS*","*MENSAJE RECORDATORIO 🚨*"&"%0A"&"%0A"&"Hola, "&D15&"."&"%0A"&"Te quedan "&K15&" Dias restantes para renovar su cuenta de *CLARO VIDEO*")),"💰") -> 💰 | M15: =HYPERLINK("https://api.whatsapp.com/send?phone="&E15&"&text=*🔴 Cambio de contraseña: Claro Video*"&"%0A"&"%0A"&"💻 Correo: *"&G15&"*"&"%0A"&"🔐 Nueva Contraseña: *"&H15&"*","🔐") -> 🔐 | N15: =HYPERLINK("https://api.whatsapp.com/send?phone=51"&E15&"&text=*🔴 CLARO VIDEO*"&"%0A"&"%0A"&"*📧 Correo:* "&G15&"%0A"&"*🔑 Contraseña:* "&H15&"%0A"&"%0A"&"*🖥 Perfil:* "&C15&"%0A"&"%0A"&"*📍 Vence:* "&J15,"💻") -> 💻 | Q15: 30/9/23 | R15: =Q15-TODAY() -> -193
K16: =J16-K$12 -> -45392 | L16: =HYPERLINK("https://api.whatsapp.com/send?phone="&E16&"&text="&(IF(K16<=0,"🚨 Hola, *"&D16&".*"&"%0A"&"Su cuenta de Claro Video vencio, Porfavor renueve si aun desea el servicio."&"%0A"&"*Tiene todo el dia para realizar el pago de lo contrario al dia siguiente sera suspendida*"&"%0A"&"*GRACIAS*","*MENSAJE RECORDATORIO 🚨*"&"%0A"&"%0A"&"Hola, "&D16&"."&"%0A"&"Te quedan "&K16&" Dias restantes para renovar su cuenta de *CLARO VIDEO*")),"💰") -> 💰 | M16: =HYPERLINK("https://api.whatsapp.com/send?phone="&E16&"&text=*🔴 Cambio de contraseña: Claro Video*"&"%0A"&"%0A"&"💻 Correo: *"&G16&"*"&"%0A"&"🔐 Nueva Contraseña: *"&H16&"*","🔐") -> 🔐 | N16: =HYPERLINK("https://api.whatsapp.com/send?phone=51"&E16&"&text=*🔴 CLARO VIDEO*"&"%0A"&"%0A"&"*📧 Correo:* "&G16&"%0A"&"*🔑 Contraseña:* "&H16&"%0A"&"%0A"&"*🖥 Perfil:* "&C16&"%0A"&"%0A"&"*📍 Vence:* "&J16,"💻") -> 💻 | Q16: 30/9/23 | R16: =Q16-TODAY() -> -193
K17: =J17-K$12 -> -45392 | L17: =HYPERLINK("https://api.whatsapp.com/send?phone="&E17&"&text="&(IF(K17<=0,"🚨 Hola, *"&D17&".*"&"%0A"&"Su cuenta de Claro Video vencio, Porfavor renueve si aun desea el servicio."&"%0A"&"*Tiene todo el dia para realizar el pago de lo contrario al dia siguiente sera suspendida*"&"%0A"&"*GRACIAS*","*MENSAJE RECORDATORIO 🚨*"&"%0A"&"%0A"&"Hola, "&D17&"."&"%0A"&"Te quedan "&K17&" Dias restantes para renovar su cuenta de *CLARO VIDEO*")),"💰") -> 💰 | M17: =HYPERLINK("https://api.whatsapp.com/send?phone="&E17&"&text=*🔴 Cambio de contraseña: Claro Video*"&"%0A"&"%0A"&"💻 Correo: *"&G17&"*"&"%0A"&"🔐 Nueva Contraseña: *"&H17&"*","🔐") -> 🔐 | N17: =HYPERLINK("https://api.whatsapp.com/send?phone=51"&E17&"&text=*🔴 CLARO VIDEO*"&"%0A"&"%0A"&"*📧 Correo:* "&G17&"%0A"&"*🔑 Contraseña:* "&H17&"%0A"&"%0A"&"*🖥 Perfil:* "&C17&"%0A"&"%0A"&"*📍 Vence:* "&J17,"💻") -> 💻 | Q17: 30/9/23 | R17: =Q17-TODAY() -> -193
K18: =J18-K$12 -> -45392 | L18: =HYPERLINK("https://api.whatsapp.com/send?phone="&E18&"&text="&(IF(K18<=0,"🚨 Hola, *"&D18&".*"&"%0A"&"Su cuenta de Claro Video vencio, Porfavor renueve si aun desea el servicio."&"%0A"&"*Tiene todo el dia para realizar el pago de lo contrario al dia siguiente sera suspendida*"&"%0A"&"*GRACIAS*","*MENSAJE RECORDATORIO 🚨*"&"%0A"&"%0A"&"Hola, "&D18&"."&"%0A"&"Te quedan "&K18&" Dias restantes para renovar su cuenta de *CLARO VIDEO*")),"💰") -> 💰 | M18: =HYPERLINK("https://api.whatsapp.com/send?phone="&E18&"&text=*🔴 Cambio de contraseña: Claro Video*"&"%0A"&"%0A"&"💻 Correo: *"&G18&"*"&"%0A"&"🔐 Nueva Contraseña: *"&H18&"*","🔐") -> 🔐 | N18: =HYPERLINK("https://api.whatsapp.com/send?phone=51"&E18&"&text=*🔴 CLARO VIDEO*"&"%0A"&"%0A"&"*📧 Correo:* "&G18&"%0A"&"*🔑 Contraseña:* "&H18&"%0A"&"%0A"&"*🖥 Perfil:* "&C18&"%0A"&"%0A"&"*📍 Vence:* "&J18,"💻") -> 💻 | Q18: 30/9/23 | R18: =Q18-TODAY() -> -193
D20: NOMBRE | E20: CELULAR | F20: VENDEDOR | G20: CORREO | H20: CLAVE | I20: PAGÓ | J20: TERMINA | K20: DIAS | L20: COBRAR | M20: RTB | N20: PERFILES | O20: PROOVEDOR | P20: COSTÓ | Q20: TERMINA | R20: DIAS
D21: Misael | E21: 945174408 | F21: 111 | G21: claro@gmail.com | H21: PRUEBA | I21: 45 | J21: 30/8/23 | K21: =J21-K$12 -> -224 | L21: =HYPERLINK("https://api.whatsapp.com/send?phone="&E21&"&text="&(IF(K21<=0,"🚨 Hola, *"&D21&".*"&"%0A"&"Su cuenta de Claro Video vencio, Porfavor renueve si aun desea el servicio."&"%0A"&"*Tiene todo el dia para realizar el pago de lo contrario al dia siguiente sera suspendida*"&"%0A"&"*GRACIAS*","*MENSAJE RECORDATORIO 🚨*"&"%0A"&"%0A"&"Hola, "&D21&"."&"%0A"&"Te quedan "&K21&" Dias restantes para renovar su cuenta de *CLARO VIDEO*")),"💰") -> 💰 | M21: =HYPERLINK("https://api.whatsapp.com/send?phone="&E21&"&text=*🔴 Cambio de contraseña: Claro Video*"&"%0A"&"%0A"&"💻 Correo: *"&G21&"*"&"%0A"&"🔐 Nueva Contraseña: *"&H21&"*","🔐") -> 🔐 | N21: =HYPERLINK("https://api.whatsapp.com/send?phone=51"&E21&"&text=*🔴 CLARO VIDEO COMPLETO*"&"%0A"&"%0A"&"*📧 Correo:* "&G21&"%0A"&"*🔑 Contraseña:* "&H21&"%0A"&"%0A"&"*🖥 Perfil:* "&D21&"%0A"&"%0A"&"*📍 Vence:* "&J21,"💻") -> 💻 | O21: MISAEL | P21: 8 | Q21: 30/9/23 | R21: =Q21-TODAY() -> -193
K23: =TODAY() -> 45392 | L23: BOTONES | P23: DATOS DE LA CUENTA
C24: PERFIL | D24: NOMBRE | E24: CELULAR | F24: VENDEDOR | G24: CORREO | H24: CLAVE | I24: PAGÓ | J24: TERMINA | K24: DIAS | L24: COBRAR | M24: RTB | N24: PERFILES | O24: PROOVEDOR | P24: COSTÓ | Q24: TERMINA | R24: DIAS
K25: =J25-K$12 -> -45392 | L25: =HYPERLINK("https://api.whatsapp.com/send?phone="&E25&"&text="&(IF(K25<=0,"🚨 Hola, *"&D25&".*"&"%0A"&"Su cuenta de Claro Video vencio, Porfavor renueve si aun desea el servicio."&"%0A"&"*Tiene todo el dia para realizar el pago de lo contrario al dia siguiente sera suspendida*"&"%0A"&"*GRACIAS*","*MENSAJE RECORDATORIO 🚨*"&"%0A"&"%0A"&"Hola, "&D25&"."&"%0A"&"Te quedan "&K25&" Dias restantes para renovar su cuenta de *CLARO VIDEO*")),"💰") -> 💰 | M25: =HYPERLINK("https://api.whatsapp.com/send?phone="&E25&"&text=*🔴 Cambio de contraseña: Claro Video*"&"%0A"&"%0A"&"💻 Correo: *"&G25&"*"&"%0A"&"🔐 Nueva Contraseña: *"&H25&"*","🔐") -> 🔐 | N25: =HYPERLINK("https://api.whatsapp.com/send?phone=51"&E25&"&text=*🔴 CLARO VIDEO*"&"%0A"&"%0A"&"*📧 Correo:* "&G25&"%0A"&"*🔑 Contraseña:* "&H25&"%0A"&"%0A"&"*🖥 Perfil:* "&C25&"%0A"&"%0A"&"*📍 Vence:* "&J25,"💻") -> 💻 | R25: =Q25-TODAY() -> -45392
K26: =J26-K$12 -> -45392 | L26: =HYPERLINK("https://api.whatsapp.com/send?phone="&E26&"&text="&(IF(K26<=0,"🚨 Hola, *"&D26&".*"&"%0A"&"Su cuenta de Claro Video vencio, Porfavor renueve si aun desea el servicio."&"%0A"&"*Tiene todo el dia para realizar el pago de lo contrario al dia siguiente sera suspendida*"&"%0A"&"*GRACIAS*","*MENSAJE RECORDATORIO 🚨*"&"%0A"&"%0A"&"Hola, "&D26&"."&"%0A"&"Te quedan "&K26&" Dias restantes para renovar su cuenta de *CLARO VIDEO*")),"💰") -> 💰 | M26: =HYPERLINK("https://api.whatsapp.com/send?phone="&E26&"&text=*🔴 Cambio de contraseña: Claro Video*"&"%0A"&"%0A"&"💻 Correo: *"&G26&"*"&"%0A"&"🔐 Nueva Contraseña: *"&H26&"*","🔐") -> 🔐 | N26: =HYPERLINK("https://api.whatsapp.com/send?phone=51"&E26&"&text=*🔴 CLARO VIDEO*"&"%0A"&"%0A"&"*📧 Correo:* "&G26&"%0A"&"*🔑 Contraseña:* "&H26&"%0A"&"%0A"&"*🖥 Perfil:* "&C26&"%0A"&"%0A"&"*📍 Vence:* "&J26,"💻") -> 💻 | R26: =Q26-TODAY() -> -45392
K27: =J27-K$12 -> -45392 | L27: =HYPERLINK("https://api.whatsapp.com/send?phone="&E27&"&text="&(IF(K27<=0,"🚨 Hola, *"&D27&".*"&"%0A"&"Su cuenta de Claro Video vencio, Porfavor renueve si aun desea el servicio."&"%0A"&"*Tiene todo el dia para realizar el pago de lo contrario al dia siguiente sera suspendida*"&"%0A"&"*GRACIAS*","*MENSAJE RECORDATORIO 🚨*"&"%0A"&"%0A"&"Hola, "&D27&"."&"%0A"&"Te quedan "&K27&" Dias restantes para renovar su cuenta de *CLARO VIDEO*")),"💰") -> 💰 | M27: =HYPERLINK("https://api.whatsapp.com/send?phone="&E27&"&text=*🔴 Cambio de contraseña: Claro Video*"&"%0A"&"%0A"&"💻 Correo: *"&G27&"*"&"%0A"&"🔐 Nueva Contraseña: *"&H27&"*","🔐") -> 🔐 | N27: =HYPERLINK("https://api.whatsapp.com/send?phone=51"&E27&"&text=*🔴 CLARO VIDEO*"&"%0A"&"%0A"&"*📧 Correo:* "&G27&"%0A"&"*🔑 Contraseña:* "&H27&"%0A"&"%0A"&"*🖥 Perfil:* "&C27&"%0A"&"%0A"&"*📍 Vence:* "&J27,"💻") -> 💻 | R27: =Q27-TODAY() -> -45392
K28: =J28-K$12 -> -45392 | L28: =HYPERLINK("https://api.whatsapp.com/send?phone="&E28&"&text="&(IF(K28<=0,"🚨 Hola, *"&D28&".*"&"%0A"&"Su cuenta de Claro Video vencio, Porfavor renueve si aun desea el servicio."&"%0A"&"*Tiene todo el dia para realizar el pago de lo contrario al dia siguiente sera suspendida*"&"%0A"&"*GRACIAS*","*MENSAJE RECORDATORIO 🚨*"&"%0A"&"%0A"&"Hola, "&D28&"."&"%0A"&"Te quedan "&K28&" Dias restantes para renovar su cuenta de *CLARO VIDEO*")),"💰") -> 💰 | M28: =HYPERLINK("https://api.whatsapp.com/send?phone="&E28&"&text=*🔴 Cambio de contraseña: Claro Video*"&"%0A"&"%0A"&"💻 Correo: *"&G28&"*"&"%0A"&"🔐 Nueva Contraseña: *"&H28&"*","🔐") -> 🔐 | N28: =HYPERLINK("https://api.whatsapp.com/send?phone=51"&E28&"&text=*🔴 CLARO VIDEO*"&"%0A"&"%0A"&"*📧 Correo:* "&G28&"%0A"&"*🔑 Contraseña:* "&H28&"%0A"&"%0A"&"*🖥 Perfil:* "&C28&"%0A"&"%0A"&"*📍 Vence:* "&J28,"💻") -> 💻 | R28: =Q28-TODAY() -> -45392
K29: =J29-K$12 -> -45392 | L29: =HYPERLINK("https://api.whatsapp.com/send?phone="&E29&"&text="&(IF(K29<=0,"🚨 Hola, *"&D29&".*"&"%0A"&"Su cuenta de Claro Video vencio, Porfavor renueve si aun desea el servicio."&"%0A"&"*Tiene todo el dia para realizar el pago de lo contrario al dia siguiente sera suspendida*"&"%0A"&"*GRACIAS*","*MENSAJE RECORDATORIO 🚨*"&"%0A"&"%0A"&"Hola, "&D29&"."&"%0A"&"Te quedan "&K29&" Dias restantes para renovar su cuenta de *CLARO VIDEO*")),"💰") -> 💰 | M29: =HYPERLINK("https://api.whatsapp.com/send?phone="&E29&"&text=*🔴 Cambio de contraseña: Claro Video*"&"%0A"&"%0A"&"💻 Correo: *"&G29&"*"&"%0A"&"🔐 Nueva Contraseña: *"&H29&"*","🔐") -> 🔐 | N29: =HYPERLINK("https://api.whatsapp.com/send?phone=51"&E29&"&text=*🔴 CLARO VIDEO*"&"%0A"&"%0A"&"*📧 Correo:* "&G29&"%0A"&"*🔑 Contraseña:* "&H29&"%0A"&"%0A"&"*🖥 Perfil:* "&C29&"%0A"&"%0A"&"*📍 Vence:* "&J29,"💻") -> 💻 | R29: =Q29-TODAY() -> -45392

Sheet DISNEY
L11: ="GANANCIAS: "&SUM(I14:I866) -> GANANCIAS: 25
K12: =TODAY() -> 45392 | L12: BOTONES | P12: DATOS DE LA CUENTA
C13: PERFIL | D13: NOMBRE | E13: CELULAR | F13: PIN | G13: CORREO | H13: CLAVE | I13: PAGÓ | J13: TERMINA | K13: DIAS | L13: COBRAR | M13: RTB | N13: PERFILES | O13: PROOVEDOR | P13: COSTÓ | Q13: TERMINA | R13: DIAS
C14: Misa | D14: Misael | E14: 945174408 | F14: 2587 | G14: disney@gmail.com | H14: PRUEBA | I14: 7 | J14: 30/8/23 | K14: =J14-K$12 -> -224 | L14: =HYPERLINK("https://api.whatsapp.com/send?phone="&E14&"&text="&(IF(K14<=0,"🚨 Hola, *"&D14&".*"&"%0A"&"Su cuenta de Disney Plus vencio, Porfavor renueve si aun desea el servicio."&"%0A"&"*Tiene todo el dia para realizar el pago de lo contrario al dia siguiente sera suspendida*"&"%0A"&"*GRACIAS*","*MENSAJE RECORDATORIO 🚨*"&"%0A"&"%0A"&"Hola, "&D14&"."&"%0A"&"Te quedan "&K14&" Dias restantes para renovar su cuenta de *Disney Plus*")),"💰") -> 💰 | M14: =HYPERLINK("https://api.whatsapp.com/send?phone="&E14&"&text=*🔴 Cambio de Contraseña: Disney Plus*"&"%0A"&"%0A"&"💻 Correo: *"&G14&"*"&"%0A"&"🔐 Nueva Contraseña: *"&H14&"*","🔐") -> 🔐 | N14: =HYPERLINK("https://api.whatsapp.com/send?phone=51"&E14&"&text=*🔴 DISNEY PLUS*"&"%0A"&"%0A"&"*📧 Correo:* "&G14&"%0A"&"*🔑 Contraseña:* "&H14&"%0A"&"%0A"&"*🖥 Perfil:* "&C14&" - "&F14&"%0A"&"%0A"&"*📍 Vence:* "&J14,"💻") -> 💻 | O14: MISAEL | P14: 8 | Q14: 30/9/23 | R14: =Q14-TODAY() -> -193
K15: =J15-K$12 -> -45392 | L15: =HYPERLINK("https://api.whatsapp.com/send?phone="&E15&"&text="&(IF(K15<=0,"🚨 Hola, *"&D15&".*"&"%0A"&"Su cuenta de Disney Plus vencio, Porfavor renueve si aun desea el servicio."&"%0A"&"*Tiene todo el dia para realizar el pago de lo contrario al dia siguiente sera suspendida*"&"%0A"&"*GRACIAS*","*MENSAJE RECORDATORIO 🚨*"&"%0A"&"%0A"&"Hola, "&D15&"."&"%0A"&"Te quedan "&K15&" Dias restantes para renovar su cuenta de *Disney Plus*")),"💰") -> 💰 | M15: =HYPERLINK("https://api.whatsapp.com/send?phone="&E15&"&text=*🔴 Cambio de Contraseña: Disney Plus*"&"%0A"&"%0A"&"💻 Correo: *"&G15&"*"&"%0A"&"🔐 Nueva Contraseña: *"&H15&"*","🔐") -> 🔐 | N15: =HYPERLINK("https://api.whatsapp.com/send?phone=51"&E15&"&text=*🔴 DISNEY PLUS*"&"%0A"&"%0A"&"*📧 Correo:* "&G15&"%0A"&"*🔑 Contraseña:* "&H15&"%0A"&"%0A"&"*🖥 Perfil:* "&C15&" - "&F15&"%0A"&"%0A"&"*📍 Vence:* "&J15,"💻") -> 💻 | R15: =Q15-TODAY() -> -45392
K16: =J16-K$12 -> -45392 | L16: =HYPERLINK("https://api.whatsapp.com/send?phone="&E16&"&text="&(IF(K16<=0,"🚨 Hola, *"&D16&".*"&"%0A"&"Su cuenta de Disney Plus vencio, Porfavor renueve si aun desea el servicio."&"%0A"&"*Tiene todo el dia para realizar el pago de lo contrario al dia siguiente sera suspendida*"&"%0A"&"*GRACIAS*","*MENSAJE RECORDATORIO 🚨*"&"%0A"&"%0A"&"Hola, "&D16&"."&"%0A"&"Te quedan "&K16&" Dias restantes para renovar su cuenta de *Disney Plus*")),"💰") -> 💰 | M16: =HYPERLINK("https://api.whatsapp.com/send?phone="&E16&"&text=*🔴 Cambio de Contraseña: Disney Plus*"&"%0A"&"%0A"&"💻 Correo: *"&G16&"*"&"%0A"&"🔐 Nueva Contraseña: *"&H16&"*","🔐") -> 🔐 | N16: =HYPERLINK("https://api.whatsapp.com/send?phone=51"&E16&"&text=*🔴 DISNEY PLUS*"&"%0A"&"%0A"&"*📧 Correo:* "&G16&"%0A"&"*🔑 Contraseña:* "&H16&"%0A"&"%0A"&"*🖥 Perfil:* "&C16&" - "&F16&"%0A"&"%0A"&"*📍 Vence:* "&J16,"💻") -> 💻 | R16: =Q16-TODAY() -> -45392
K17: =J17-K$12 -> -45392 | L17: =HYPERLINK("https://api.whatsapp.com/send?phone="&E17&"&text="&(IF(K17<=0,"🚨 Hola, *"&D17&".*"&"%0A"&"Su cuenta de Disney Plus vencio, Porfavor renueve si aun desea el servicio."&"%0A"&"*Tiene todo el dia para realizar el pago de lo contrario al dia siguiente sera suspendida*"&"%0A"&"*GRACIAS*","*MENSAJE RECORDATORIO 🚨*"&"%0A"&"%0A"&"Hola, "&D17&"."&"%0A"&"Te quedan "&K17&" Dias restantes para renovar su cuenta de *Disney Plus*")),"💰") -> 💰 | M17: =HYPERLINK("https://api.whatsapp.com/send?phone="&E17&"&text=*🔴 Cambio de Contraseña: Disney Plus*"&"%0A"&"%0A"&"💻 Correo: *"&G17&"*"&"%0A"&"🔐 Nueva Contraseña: *"&H17&"*","🔐") -> 🔐 | N17: =HYPERLINK("https://api.whatsapp.com/send?phone=51"&E17&"&text=*🔴 DISNEY PLUS*"&"%0A"&"%0A"&"*📧 Correo:* "&G17&"%0A"&"*🔑 Contraseña:* "&H17&"%0A"&"%0A"&"*🖥 Perfil:* "&C17&" - "&F17&"%0A"&"%0A"&"*📍 Vence:* "&J17,"💻") -> 💻 | R17: =Q17-TODAY() -> -45392
K18: =J18-K$12 -> -45392 | L18: =HYPERLINK("https://api.whatsapp.com/send?phone="&E18&"&text="&(IF(K18<=0,"🚨 Hola, *"&D18&".*"&"%0A"&"Su cuenta de Disney Plus vencio, Porfavor renueve si aun desea el servicio."&"%0A"&"*Tiene todo el dia para realizar el pago de lo contrario al dia siguiente sera suspendida*"&"%0A"&"*GRACIAS*","*MENSAJE RECORDATORIO 🚨*"&"%0A"&"%0A"&"Hola, "&D18&"."&"%0A"&"Te quedan "&K18&" Dias restantes para renovar su cuenta de *Disney Plus*")),"💰") -> 💰 | M18: =HYPERLINK("https://api.whatsapp.com/send?phone="&E18&"&text=*🔴 Cambio de Contraseña: Disney Plus*"&"%0A"&"%0A"&"💻 Correo: *"&G18&"*"&"%0A"&"🔐 Nueva Contraseña: *"&H18&"*","🔐") -> 🔐 | N18: =HYPERLINK("https://api.whatsapp.com/send?phone=51"&E18&"&text=*🔴 DISNEY PLUS*"&"%0A"&"%0A"&"*📧 Correo:* "&G18&"%0A"&"*🔑 Contraseña:* "&H18&"%0A"&"%0A"&"*🖥 Perfil:* "&C18&" - "&F18&"%0A"&"%0A"&"*📍 Vence:* "&J18,"💻") -> 💻 | R18: =Q18-TODAY() -> -45392
K19: =J19-K$12 -> -45392 | L19: =HYPERLINK("https://api.whatsapp.com/send?phone="&E19&"&text="&(IF(K19<=0,"🚨 Hola, *"&D19&".*"&"%0A"&"Su cuenta de Disney Plus vencio, Porfavor renueve si aun desea el servicio."&"%0A"&"*Tiene todo el dia para realizar el pago de lo contrario al dia siguiente sera suspendida*"&"%0A"&"*GRACIAS*","*MENSAJE RECORDATORIO 🚨*"&"%0A"&"%0A"&"Hola, "&D19&"."&"%0A"&"Te quedan "&K19&" Dias restantes para renovar su cuenta de *Disney Plus*")),"💰") -> 💰 | M19: =HYPERLINK("https://api.whatsapp.com/send?phone="&E19&"&text=*🔴 Cambio de Contraseña: Disney Plus*"&"%0A"&"%0A"&"💻 Correo: *"&G19&"*"&"%0A"&"🔐 Nueva Contraseña: *"&H19&"*","🔐") -> 🔐 | N19: =HYPERLINK("https://api.whatsapp.com/send?phone=51"&E19&"&text=*🔴 DISNEY PLUS*"&"%0A"&"%0A"&"*📧 Correo:* "&G19&"%0A"&"*🔑 Contraseña:* "&H19&"%0A"&"%0A"&"*🖥 Perfil:* "&C19&" - "&F19&"%0A"&"%0A"&"*📍 Vence:* "&J19,"💻") -> 💻 | R19: =Q19-TODAY() -> -45392
K20: =J20-K$12 -> -45392 | L20: =HYPERLINK("https://api.whatsapp.com/send?phone="&E20&"&text="&(IF(K20<=0,"🚨 Hola, *"&D20&".*"&"%0A"&"Su cuenta de Disney Plus vencio, Porfavor renueve si aun desea el servicio."&"%0A"&"*Tiene todo el dia para realizar el pago de lo contrario al dia siguiente sera suspendida*"&"%0A"&"*GRACIAS*","*MENSAJE RECORDATORIO 🚨*"&"%0A"&"%0A"&"Hola, "&D20&"."&"%0A"&"Te quedan "&K20&" Dias restantes para renovar su cuenta de *Disney Plus*")),"💰") -> 💰 | M20: =HYPERLINK("https://api.whatsapp.com/send?phone="&E20&"&text=*🔴 Cambio de Contraseña: Disney Plus*"&"%0A"&"%0A"&"💻 Correo: *"&G20&"*"&"%0A"&"🔐 Nueva Contraseña: *"&H20&"*","🔐") -> 🔐 | N20: =HYPERLINK("https://api.whatsapp.com/send?phone=51"&E20&"&text=*🔴 DISNEY PLUS*"&"%0A"&"%0A"&"*📧 Correo:* "&G20&"%0A"&"*🔑 Contraseña:* "&H20&"%0A"&"%0A"&"*🖥 Perfil:* "&C20&" - "&F20&"%0A"&"%0A"&"*📍 Vence:* "&J20,"💻") -> 💻 | R20: =Q20-TODAY() -> -45392
D22: NOMBRE | E22: CELULAR | F22: PIN | G22: CORREO | H22: CLAVE | I22: PAGÓ | J22: TERMINA | K22: DIAS | L22: COBRAR | M22: RTB | N22: PERFILES | O22: PROOVEDOR | P22: COSTÓ | Q22: TERMINA | R22: DIAS
D23: Misael | E23: 945174408 | G23: prueba@gmail.com | H23: PRUEBA | I23: 18 | J23: 30/8/23 | K23: =J23-K$12 -> -224 | L23: =HYPERLINK("https://api.whatsapp.com/send?phone="&E23&"&text="&(IF(K23<=0,"🚨 Hola, *"&D23&".*"&"%0A"&"Su cuenta de Disney Plus vencio, Porfavor renueve si aun desea el servicio."&"%0A"&"*Tiene todo el dia para realizar el pago de lo contrario al dia siguiente sera suspendida*"&"%0A"&"*GRACIAS*","*MENSAJE RECORDATORIO 🚨*"&"%0A"&"%0A"&"Hola, "&D23&"."&"%0A"&"Te quedan "&K23&" Dias restantes para renovar su cuenta de *Disney Plus*")),"💰") -> 💰 | M23: =HYPERLINK("https://api.whatsapp.com/send?phone="&E23&"&text=*🔴 Cambio de Contraseña: Disney Plus*"&"%0A"&"%0A"&"💻 Correo: *"&G23&"*"&"%0A"&"🔐 Nueva Contraseña: *"&H23&"*","🔐") -> 🔐 | N23: =HYPERLINK("https://api.whatsapp.com/send?phone=51"&E23&"&text=*🔴 DISNEY PLUS COMPLETO*"&"%0A"&"%0A"&"*📧 Correo:* "&G23&"%0A"&"*🔑 Contraseña:* "&H23&"%0A"&"%0A"&"*🖥 Perfil:* "&D23&"%0A"&"%0A"&"*📍 Vence:* "&J23,"💻") -> 💻 | O23: MISAEL | P23: 8 | Q23: 30/9/23 | R23: =Q23-TODAY() -> -193
K25: =TODAY() -> 45392 | L25: BOTONES | P25: DATOS DE LA CUENTA
C26: PERFIL | D26: NOMBRE | E26: CELULAR | F26: PIN | G26: CORREO | H26: CLAVE | I26: PAGÓ | J26: TERMINA | K26: DIAS | L26: COBRAR | M26: RTB | N26: PERFILES | O26: PROOVEDOR | P26: COSTÓ | Q26: TERMINA | R26: DIAS
K27: =J27-K$12 -> -45392 | L27: =HYPERLINK("https://api.whatsapp.com/send?phone="&E27&"&text="&(IF(K27<=0,"🚨 Hola, *"&D27&".*"&"%0A"&"Su cuenta de Disney Plus vencio, Porfavor renueve si aun desea el servicio."&"%0A"&"*Tiene todo el dia para realizar el pago de lo contrario al dia siguiente sera suspendida*"&"%0A"&"*GRACIAS*","*MENSAJE RECORDATORIO 🚨*"&"%0A"&"%0A"&"Hola, "&D27&"."&"%0A"&"Te quedan "&K27&" Dias restantes para renovar su cuenta de *Disney Plus*")),"💰") -> 💰 | M27: =HYPERLINK("https://api.whatsapp.com/send?phone="&E27&"&text=*🔴 Cambio de Contraseña: Disney Plus*"&"%0A"&"%0A"&"💻 Correo: *"&G27&"*"&"%0A"&"🔐 Nueva Contraseña: *"&H27&"*","🔐") -> 🔐 | N27: =HYPERLINK("https://api.whatsapp.com/send?phone=51"&E27&"&text=*🔴 DISNEY PLUS*"&"%0A"&"%0A"&"*📧 Correo:* "&G27&"%0A"&"*🔑 Contraseña:* "&H27&"%0A"&"%0A"&"*🖥 Perfil:* "&C27&" - "&F27&"%0A"&"%0A"&"*📍 Vence:* "&J27,"💻") -> 💻 | R27: =Q27-TODAY() -> -45392
K28: =J28-K$12 -> -45392 | L28: =HYPERLINK("https://api.whatsapp.com/send?phone="&E28&"&text="&(IF(K28<=0,"🚨 Hola, *"&D28&".*"&"%0A"&"Su cuenta de Disney Plus vencio, Porfavor renueve si aun desea el servicio."&"%0A"&"*Tiene todo el dia para realizar el pago de lo contrario al dia siguiente sera suspendida*"&"%0A"&"*GRACIAS*","*MENSAJE RECORDATORIO 🚨*"&"%0A"&"%0A"&"Hola, "&D28&"."&"%0A"&"Te quedan "&K28&" Dias restantes para renovar su cuenta de *Disney Plus*")),"💰") -> 💰 | M28: =HYPERLINK("https://api.whatsapp.com/send?phone="&E28&"&text=*🔴 Cambio de Contraseña: Disney Plus*"&"%0A"&"%0A"&"💻 Correo: *"&G28&"*"&"%0A"&"🔐 Nueva Contraseña: *"&H28&"*","🔐") -> 🔐 | N28: =HYPERLINK("https://api.whatsapp.com/send?phone=51"&E28&"&text=*🔴 DISNEY PLUS*"&"%0A"&"%0A"&"*📧 Correo:* "&G28&"%0A"&"*🔑 Contraseña:* "&H28&"%0A"&"%0A"&"*🖥 Perfil:* "&C28&" - "&F28&"%0A"&"%0A"&"*📍 Vence:* "&J28,"💻") -> 💻 | R28: =Q28-TODAY() -> -45392
K29: =J29-K$12 -> -45392 | L29: =HYPERLINK("https://api.whatsapp.com/send?phone="&E29&"&text="&(IF(K29<=0,"🚨 Hola, *"&D29&".*"&"%0A"&"Su cuenta de Disney Plus vencio, Porfavor renueve si aun desea el servicio."&"%0A"&"*Tiene todo el dia para realizar el pago de lo contrario al dia siguiente sera suspendida*"&"%0A"&"*GRACIAS*","*MENSAJE RECORDATORIO 🚨*"&"%0A"&"%0A"&"Hola, "&D29&"."&"%0A"&"Te quedan "&K29&" Dias restantes para renovar su cuenta de *Disney Plus*")),"💰") -> 💰 | M29: =HYPERLINK("https://api.whatsapp.com/send?phone="&E29&"&text=*🔴 Cambio de Contraseña: Disney Plus*"&"%0A"&"%0A"&"💻 Correo: *"&G29&"*"&"%0A"&"🔐 Nueva Contraseña: *"&H29&"*","🔐") -> 🔐 | N29: =HYPERLINK("https://api.whatsapp.com/send?phone=51"&E29&"&text=*🔴 DISNEY PLUS*"&"%0A"&"%0A"&"*📧 Correo:* "&G29&"%0A"&"*🔑 Contraseña:* "&H29&"%0A"&"%0A"&"*🖥 Perfil:* "&C29&" - "&F29&"%0A"&"%0A"&"*📍 Vence:* "&J29,"💻") -> 💻 | R29: =Q29-TODAY() -> -45392
K30: =J30-K$12 -> -45392 | L30: =HYPERLINK("https://api.whatsapp.com/send?phone="&E30&"&text="&(IF(K30<=0,"🚨 Hola, *"&D30&".*"&"%0A"&"Su cuenta de Disney Plus vencio, Porfavor renueve si aun desea el servicio."&"%0A"&"*Tiene todo el dia para realizar el pago de lo contrario al dia siguiente sera suspendida*"&"%0A"&"*GRACIAS*","*MENSAJE RECORDATORIO 🚨*"&"%0A"&"%0A"&"Hola, "&D30&"."&"%0A"&"Te quedan "&K30&" Dias restantes para renovar su cuenta de *Disney Plus*")),"💰") -> 💰 | M30: =HYPERLINK("https://api.whatsapp.com/send?phone="&E30&"&text=*🔴 Cambio de Contraseña: Disney Plus*"&"%0A"&"%0A"&"💻 Correo: *"&G30&"*"&"%0A"&"🔐 Nueva Contraseña: *"&H30&"*","🔐") -> 🔐 | N30: =HYPERLINK("https://api.whatsapp.com/send?phone=51"&E30&"&text=*🔴 DISNEY PLUS*"&"%0A"&"%0A"&"*📧 Correo:* "&G30&"%0A"&"*🔑 Contraseña:* "&H30&"%0A"&"%0A"&"*🖥 Perfil:* "&C30&" - "&F30&"%0A"&"%0A"&"*📍 Vence:* "&J30,"💻") -> 💻 | R30: =Q30-TODAY() -> -45392
K31: =J31-K$12 -> -45392 | L31: =HYPERLINK("https://api.whatsapp.com/send?phone="&E31&"&text="&(IF(K31<=0,"🚨 Hola, *"&D31&".*"&"%0A"&"Su cuenta de Disney Plus vencio, Porfavor renueve si aun desea el servicio."&"%0A"&"*Tiene todo el dia para realizar el pago de lo contrario al dia siguiente sera suspendida*"&"%0A"&"*GRACIAS*","*MENSAJE RECORDATORIO 🚨*"&"%0A"&"%0A"&"Hola, "&D31&"."&"%0A"&"Te quedan "&K31&" Dias restantes para renovar su cuenta de *Disney Plus*")),"💰") -> 💰 | M31: =HYPERLINK("https://api.whatsapp.com/send?phone="&E31&"&text=*🔴 Cambio de Contraseña: Disney Plus*"&"%0A"&"%0A"&"💻 Correo: *"&G31&"*"&"%0A"&"🔐 Nueva Contraseña: *"&H31&"*","🔐") -> 🔐 | N31: =HYPERLINK("https://api.whatsapp.com/send?phone=51"&E31&"&text=*🔴 DISNEY PLUS*"&"%0A"&"%0A"&"*📧 Correo:* "&G31&"%0A"&"*🔑 Contraseña:* "&H31&"%0A"&"%0A"&"*🖥 Perfil:* "&C31&" - "&F31&"%0A"&"%0A"&"*📍 Vence:* "&J31,"💻") -> 💻 | R31: =Q31-TODAY() -> -45392
K32: =J32-K$12 -> -45392 | L32: =HYPERLINK("https://api.whatsapp.com/send?phone="&E32&"&text="&(IF(K32<=0,"🚨 Hola, *"&D32&".*"&"%0A"&"Su cuenta de Disney Plus vencio, Porfavor renueve si aun desea el servicio."&"%0A"&"*Tiene todo el dia para realizar el pago de lo contrario al dia siguiente sera suspendida*"&"%0A"&"*GRACIAS*","*MENSAJE RECORDATORIO 🚨*"&"%0A"&"%0A"&"Hola, "&D32&"."&"%0A"&"Te quedan "&K32&" Dias restantes para renovar su cuenta de *Disney Plus*")),"💰") -> 💰 | M32: =HYPERLINK("https://api.whatsapp.com/send?phone="&E32&"&text=*🔴 Cambio de Contraseña: Disney Plus*"&"%0A"&"%0A"&"💻 Correo: *"&G32&"*"&"%0A"&"🔐 Nueva Contraseña: *"&H32&"*","🔐") -> 🔐 | N32: =HYPERLINK("https://api.whatsapp.com/send?phone=51"&E32&"&text=*🔴 DISNEY PLUS*"&"%0A"&"%0A"&"*📧 Correo:* "&G32&"%0A"&"*🔑 Contraseña:* "&H32&"%0A"&"%0A"&"*🖥 Perfil:* "&C32&" - "&F32&"%0A"&"%0A"&"*📍 Vence:* "&J32,"💻") -> 💻 | R32: =Q32-TODAY() -> -45392
K33: =J33-K$12 -> -45392 | L33: =HYPERLINK("https://api.whatsapp.com/send?phone="&E33&"&text="&(IF(K33<=0,"🚨 Hola, *"&D33&".*"&"%0A"&"Su cuenta de Disney Plus vencio, Porfavor renueve si aun desea el servicio."&"%0A"&"*Tiene todo el dia para realizar el pago de lo contrario al dia siguiente sera suspendida*"&"%0A"&"*GRACIAS*","*MENSAJE RECORDATORIO 🚨*"&"%0A"&"%0A"&"Hola, "&D33&"."&"%0A"&"Te quedan "&K33&" Dias restantes para renovar su cuenta de *Disney Plus*")),"💰") -> 💰 | M33: =HYPERLINK("https://api.whatsapp.com/send?phone="&E33&"&text=*🔴 Cambio de Contraseña: Disney Plus*"&"%0A"&"%0A"&"💻 Correo: *"&G33&"*"&"%0A"&"🔐 Nueva Contraseña: *"&H33&"*","🔐") -> 🔐 | N33: =HYPERLINK("https://api.whatsapp.com/send?phone=51"&E33&"&text=*🔴 DISNEY PLUS*"&"%0A"&"%0A"&"*📧 Correo:* "&G33&"%0A"&"*🔑 Contraseña:* "&H33&"%0A"&"%0A"&"*🖥 Perfil:* "&C33&" - "&F33&"%0A"&"%0A"&"*📍 Vence:* "&J33,"💻") -> 💻 | R33: =Q33-TODAY() -> -45392

Sheet STAR 
L11: ="GANANCIAS: "&SUM(I14:I866) -> GANANCIAS: 26
K12: =TODAY() -> 45392 | L12: BOTONES | P12: DATOS DE LA CUENTA
C13: PERFIL | D13: NOMBRE | E13: CELULAR | F13: PIN | G13: CORREO | H13: CLAVE | I13: PAGÓ | J13: TERMINA | K13: DIAS | L13: COBRAR | M13: RTB | N13: PERFILES | O13: PROOVEDOR | P13: COSTÓ | Q13: TERMINA | R13: DIAS
C14: MISA | D14: MISAEL | E14: 945174408 | F14: 2098 | G14: STARPLUS@GMAIL.COM | H14: PRUEBA | I14: 8 | J14: 30/8/23 | K14: =J14-K$12 -> -224 | L14: =HYPERLINK("https://api.whatsapp.com/send?phone="&E14&"&text="&(IF(K14<=0,"🚨 Hola, *"&D14&".*"&"%0A"&"Su cuenta de Star Plus vencio, Porfavor renueve si aun desea el servicio."&"%0A"&"*Tiene todo el dia para realizar el pago de lo contrario al dia siguiente sera suspendida*"&"%0A"&"*GRACIAS*","*MENSAJE RECORDATORIO 🚨*"&"%0A"&"%0A"&"Hola, "&D14&"."&"%0A"&"Te quedan "&K14&" Dias restantes para renovar su cuenta de *Star Plus*")),"💰") -> 💰 | M14: =HYPERLINK("https://api.whatsapp.com/send?phone="&E14&"&text=*🔴 Cambio de Contraseña: Star Plus*"&"%0A"&"%0A"&"💻 Correo: *"&G14&"*"&"%0A"&"🔐 Nueva Contraseña: *"&H14&"*","🔐") -> 🔐 | N14: =HYPERLINK("https://api.whatsapp.com/send?phone=51"&E14&"&text=*🔴 STAR PLUS*"&"%0A"&"%0A"&"*📧 Correo:* "&G14&"%0A"&"*🔑 Contraseña:* "&H14&"%0A"&"%0A"&"*🖥 Perfil:* "&C14&" - "&F14&"%0A"&"%0A"&"*📍 Vence:* "&J14,"💻") -> 💻 | O14: MISAEL | P14: 8 | Q14: 30/9/23 | R14: =Q14-TODAY() -> -193
K15: =J15-K$12 -> -45392 | L15: =HYPERLINK("https://api.whatsapp.com/send?phone="&E15&"&text="&(IF(K15<=0,"🚨 Hola, *"&D15&".*"&"%0A"&"Su cuenta de Star Plus vencio, Porfavor renueve si aun desea el servicio."&"%0A"&"*Tiene todo el dia para realizar el pago de lo contrario al dia siguiente sera suspendida*"&"%0A"&"*GRACIAS*","*MENSAJE RECORDATORIO 🚨*"&"%0A"&"%0A"&"Hola, "&D15&"."&"%0A"&"Te quedan "&K15&" Dias restantes para renovar su cuenta de *Star Plus*")),"💰") -> 💰 | M15: =HYPERLINK("https://api.whatsapp.com/send?phone="&E15&"&text=*🔴 Cambio de Contraseña: Star Plus*"&"%0A"&"%0A"&"💻 Correo: *"&G15&"*"&"%0A"&"🔐 Nueva Contraseña: *"&H15&"*","🔐") -> 🔐 | N15: =HYPERLINK("https://api.whatsapp.com/send?phone=51"&E15&"&text=*🔴 STAR PLUS*"&"%0A"&"%0A"&"*📧 Correo:* "&G15&"%0A"&"*🔑 Contraseña:* "&H15&"%0A"&"%0A"&"*🖥 Perfil:* "&C15&" - "&F15&"%0A"&"%0A"&"*📍 Vence:* "&J15,"💻") -> 💻 | R15: =Q15-TODAY() -> -45392
K16: =J16-K$12 -> -45392 | L16: =HYPERLINK("https://api.whatsapp.com/send?phone="&E16&"&text="&(IF(K16<=0,"🚨 Hola, *"&D16&".*"&"%0A"&"Su cuenta de Star Plus vencio, Porfavor renueve si aun desea el servicio."&"%0A"&"*Tiene todo el dia para realizar el pago de lo contrario al dia siguiente sera suspendida*"&"%0A"&"*GRACIAS*","*MENSAJE RECORDATORIO 🚨*"&"%0A"&"%0A"&"Hola, "&D16&"."&"%0A"&"Te quedan "&K16&" Dias restantes para renovar su cuenta de *Star Plus*")),"💰") -> 💰 | M16: =HYPERLINK("https://api.whatsapp.com/send?phone="&E16&"&text=*🔴 Cambio de Contraseña: Star Plus*"&"%0A"&"%0A"&"💻 Correo: *"&G16&"*"&"%0A"&"🔐 Nueva Contraseña: *"&H16&"*","🔐") -> 🔐 | N16: =HYPERLINK("https://api.whatsapp.com/send?phone=51"&E16&"&text=*🔴 STAR PLUS*"&"%0A"&"%0A"&"*📧 Correo:* "&G16&"%0A"&"*🔑 Contraseña:* "&H16&"%0A"&"%0A"&"*🖥 Perfil:* "&C16&" - "&F16&"%0A"&"%0A"&"*📍 Vence:* "&J16,"💻") -> 💻 | R16: =Q16-TODAY() -> -45392
